2022-12-13 06:59:58,016 INFO    StreamThr :326827 [internal.py:wandb_internal():90] W&B internal server running at pid: 326827, started at: 2022-12-13 06:59:58.015135
2022-12-13 06:59:58,020 DEBUG   HandlerThread:326827 [handler.py:handle_request():139] handle_request: status
2022-12-13 06:59:58,023 DEBUG   SenderThread:326827 [sender.py:send_request():317] send_request: status
2022-12-13 06:59:58,026 DEBUG   SenderThread:326827 [sender.py:send():303] send: header
2022-12-13 06:59:58,026 INFO    WriterThread:326827 [datastore.py:open_for_write():75] open: /home/t-chengluo/RL/MAPPO/results/abr_5G/abr_5G/ppo/check/wandb/run-20221213_065957-2jitfsmv/run-2jitfsmv.wandb
2022-12-13 06:59:58,027 DEBUG   SenderThread:326827 [sender.py:send():303] send: run
2022-12-13 06:59:58,756 ERROR   SenderThread:326827 [internal_api.py:execute():212] 403 response executing GraphQL.
2022-12-13 06:59:58,757 ERROR   SenderThread:326827 [internal_api.py:execute():213] {"errors":[{"message":"permission denied","path":["upsertBucket"],"extensions":{"code":"PERMISSION_ERROR"}}],"data":{"upsertBucket":null}}
2022-12-13 06:59:59,028 INFO    WriterThread:326827 [datastore.py:close():279] close: /home/t-chengluo/RL/MAPPO/results/abr_5G/abr_5G/ppo/check/wandb/run-20221213_065957-2jitfsmv/run-2jitfsmv.wandb
2022-12-13 06:59:59,028 INFO    HandlerThread:326827 [handler.py:finish():814] shutting down handler
2022-12-13 06:59:59,029 ERROR   StreamThr :326827 [internal.py:wandb_internal():162] Thread SenderThread:
Traceback (most recent call last):
  File "/home/t-chengluo/miniconda3/envs/carbon/lib/python3.7/site-packages/wandb/sdk/lib/retry.py", line 113, in __call__
    result = self._call_fn(*args, **kwargs)
  File "/home/t-chengluo/miniconda3/envs/carbon/lib/python3.7/site-packages/wandb/sdk/internal/internal_api.py", line 209, in execute
    return self.client.execute(*args, **kwargs)  # type: ignore
  File "/home/t-chengluo/miniconda3/envs/carbon/lib/python3.7/site-packages/wandb/vendor/gql-0.2.0/wandb_gql/client.py", line 52, in execute
    result = self._get_result(document, *args, **kwargs)
  File "/home/t-chengluo/miniconda3/envs/carbon/lib/python3.7/site-packages/wandb/vendor/gql-0.2.0/wandb_gql/client.py", line 60, in _get_result
    return self.transport.execute(document, *args, **kwargs)
  File "/home/t-chengluo/miniconda3/envs/carbon/lib/python3.7/site-packages/wandb/vendor/gql-0.2.0/wandb_gql/transport/requests.py", line 39, in execute
    request.raise_for_status()
  File "/home/t-chengluo/miniconda3/envs/carbon/lib/python3.7/site-packages/requests/models.py", line 960, in raise_for_status
    raise HTTPError(http_error_msg, response=self)
requests.exceptions.HTTPError: 403 Client Error: Forbidden for url: https://api.wandb.ai/graphql

During handling of the above exception, another exception occurred:

Traceback (most recent call last):
  File "/home/t-chengluo/miniconda3/envs/carbon/lib/python3.7/site-packages/wandb/apis/normalize.py", line 26, in wrapper
    return func(*args, **kwargs)
  File "/home/t-chengluo/miniconda3/envs/carbon/lib/python3.7/site-packages/wandb/sdk/internal/internal_api.py", line 1519, in upsert_run
    **kwargs,
  File "/home/t-chengluo/miniconda3/envs/carbon/lib/python3.7/site-packages/wandb/sdk/lib/retry.py", line 129, in __call__
    retry_timedelta_triggered = check_retry_fn(e)
  File "/home/t-chengluo/miniconda3/envs/carbon/lib/python3.7/site-packages/wandb/util.py", line 1049, in check_retry_fn
    return fallback_retry_fn(e)
  File "/home/t-chengluo/miniconda3/envs/carbon/lib/python3.7/site-packages/wandb/util.py", line 996, in no_retry_auth
    raise CommError("Permission denied, ask the project owner to grant you access")
wandb.errors.CommError: Permission denied, ask the project owner to grant you access

During handling of the above exception, another exception occurred:

Traceback (most recent call last):
  File "/home/t-chengluo/miniconda3/envs/carbon/lib/python3.7/site-packages/wandb/sdk/internal/internal_util.py", line 49, in run
    self._run()
  File "/home/t-chengluo/miniconda3/envs/carbon/lib/python3.7/site-packages/wandb/sdk/internal/internal_util.py", line 100, in _run
    self._process(record)
  File "/home/t-chengluo/miniconda3/envs/carbon/lib/python3.7/site-packages/wandb/sdk/internal/internal.py", line 309, in _process
    self._sm.send(record)
  File "/home/t-chengluo/miniconda3/envs/carbon/lib/python3.7/site-packages/wandb/sdk/internal/sender.py", line 305, in send
    send_handler(record)
  File "/home/t-chengluo/miniconda3/envs/carbon/lib/python3.7/site-packages/wandb/sdk/internal/sender.py", line 797, in send_run
    self._init_run(run, config_value_dict)
  File "/home/t-chengluo/miniconda3/envs/carbon/lib/python3.7/site-packages/wandb/sdk/internal/sender.py", line 837, in _init_run
    commit=run.git.commit or None,
  File "/home/t-chengluo/miniconda3/envs/carbon/lib/python3.7/site-packages/wandb/apis/normalize.py", line 62, in wrapper
    raise CommError(message, err).with_traceback(sys.exc_info()[2])
  File "/home/t-chengluo/miniconda3/envs/carbon/lib/python3.7/site-packages/wandb/apis/normalize.py", line 26, in wrapper
    return func(*args, **kwargs)
  File "/home/t-chengluo/miniconda3/envs/carbon/lib/python3.7/site-packages/wandb/sdk/internal/internal_api.py", line 1519, in upsert_run
    **kwargs,
  File "/home/t-chengluo/miniconda3/envs/carbon/lib/python3.7/site-packages/wandb/sdk/lib/retry.py", line 129, in __call__
    retry_timedelta_triggered = check_retry_fn(e)
  File "/home/t-chengluo/miniconda3/envs/carbon/lib/python3.7/site-packages/wandb/util.py", line 1049, in check_retry_fn
    return fallback_retry_fn(e)
  File "/home/t-chengluo/miniconda3/envs/carbon/lib/python3.7/site-packages/wandb/util.py", line 996, in no_retry_auth
    raise CommError("Permission denied, ask the project owner to grant you access")
wandb.errors.CommError: Permission denied, ask the project owner to grant you access
